Workbook

Sheet Read me
B2: PhD literature database
B3: Built from 5 BibTeX files: AIF, action control, decision making, OFC (optimal feedback control), saliency. 139 references from your files, plus 21 suggested foundational / surprise additions = 160 rows, no duplicate keys.
B5: How to use it
B6: 1. Articles sheet = one row per reference. Categorical columns (Topic, Study type, Species, Framework, Thematic file, Review section) use a controlled vocabulary so they pivot and plot cleanly.
B7: 2. Summary sheet = live COUNTIF tables + bar charts by topic, study type, framework, thematic file and species. They recalculate when you edit or filter Articles.
B8: 3. Read status / Relevance / My notes columns for details on the ref
B10: Suggested additions (the 21 new rows)
B11: 21 foundational / surprise papers that were missing from your 5 files have been added: predictive-coding & free-energy foundations (Rao & Ballard 1999, Friston/Kilner/Harrison 2006, Bastos 2012, Clark 2013, Buckley 2017, Da Costa 2020, Smith 2022, Friston curiosity 2017, Knill & Pouget 2004), surprise / novelty (Itti & Baldi 2009, Schmidhuber 2010, Barto 2013, Yu & Dayan 2005), and sensorimotor / decision foundations (Wolpert 1995, Harris & Wolpert 1998, Koerding & Wolpert 2004, Gold & Shadlen 2007, Bogacz 2006, Schultz 1997, Behrens 2007, Shadmehr 2010). They are marked Read status = "New" and Entry source = "Suggested addition - verify". Filter either column to see only them. Their full BibTeX is in additions.bib (and appended to references.bib).
B12: These additions have NOT been read either - the citation details were checked against publisher records, but verify each paper before citing.
B14: Reading priority (the Relevance 1-5 column)
B15: Every row now has a Relevance score to give reading order and importance to the review. 5 = read first, 1 = reference only. The scores are a suggested priority, biased toward the spine of the review (decisions-during-movement, optimal feedback control vs active inference, saliency-to-action, the vertex potential, and surprise). Sort or filter the Relevance column to plan your reading; treat it as a starting point and overwrite freely.
B16: 5 = read first - core to the thesis spine
... B32: Notes - relevant notes about the file

Sheet Articles
A1: CiteKey | B1: Authors | C1: Year | D1: Title | E1: Thematic file | F1: Topic | G1: Study type | H1: Species / model | I1: Task | J1: Method | K1: Computational Framework | L1: Phenomenon | M1: One-line summary | N1: Review section | O1: Source | P1: DOI / URL | Q1: Read status | R1: Scored status | S1: Relevance 1-5 | T1: Notes | U1: Abstract | V1: Entry source | W1: axis_x_engagement | X1: axis_y_action_timescale | Y1: axis_z_surprise_timescale | Z1: axis_rho_predictiveness | AA1: is_paradigm | AB1: paradigm_kind | AC1: P_PC | AD1: P_AIF | AE1: P_OFC | AF1: P_SDT | AG1: P_DDM | AH1: P_AC | AI1: P_SAL | AJ1: P_RL | AK1: dominant_account | AL1: x axis (motor task difficulty): | AM1: y axis (motor task task timescale): | AN1: z axis (external surprise hierarchy): | AO1: tr axis (Task relevance of the external stimuli): | AP1: ts axis(magnitude of external surprise) | AQ1: x_1 axis (non-motor task difficulty): | AR1: y_1 axis (non-motor task task timescale): | AS1: Com Account (dominant) | AT1: Note on task | AU1: Note on non-motor | AV1: Note on the surprise axis criteria | AW1: z1 axis (external surprise hierarchy): | AX1: tr1 axis (Task relevance of the external stimuli): | AY1: ts1 axis(magnitude of external surprise) | AZ1: z2 axis (external surprise hierarchy): | BA1: tr2 axis (Task relevance of the external stimuli): | BB1: ts2 axis(magnitude of external surprise) | BC1: z3 axis (external surprise hierarchy): | BD1: tr3 axis (Task relevance of the external stimuli): | BE1: ts3 axis(magnitude of external surprise) | BF1: scorable | BG1: confidence | BH1: score provenance | BI1: scoring note | BJ1: r axis (endo/exo)
A2: friston2003dynamic | B2: Friston, Harrison & Penny | C2: 2003 | D2: Dynamic causal modelling | E2: AIF | F2: Methods / tools | G2: Methods / tools | H2: Human | J2: Neuroimaging modelling | K2: Free-energy / active inference | M2: Introduces dynamic causal modelling to infer effective connectivity from neuroimaging. | N2: Methods / appendix | O2: Neuroimage | S2: 1 | V2: Original (.bib) | W2: 0.1 | X2: 0.1 | Y2: 0.2 | Z2: 0.5 | AA2: =FALSE() -> FALSE | AB2: theory/review | AC2: 0.239 | AD2: 0.435 | AE2: 0.043 | AF2: 0.109 | AG2: 0.043 | AH2: 0.043 | AI2: 0.043 | AJ2: 0.043 | AK2: AIF | BF2: no | BH2: not a paradigm / not reached | BI2: theory, review, model or record with no recoverable design
A3: friston2011optimal | B3: Friston | C3: 2011 | D3: What is optimal about motor control? | E3: AIF | F3: Active inference / free energy | G3: Theory / conceptual | H3: Theoretical | J3: Theory | K3: Free-energy / active inference | M3: Argues motor control is better cast as active inference than as optimal control with explicit cost functions. | N3: 2 Control frameworks | O3: Neuron | Q3: Read | S3: 5 | T3: This is one of the core ideas I want to develop and explore. The difference and transition to OFC to AIF (developed better in the manuscript) but pretty much collapsing things together and changing cost fucntions for priors and distributions. Argues active inference better naturally incorporates the action-perception loop (without the necessity of any homunculus). Therefore, argues AIF valid for any kind of naturalistic paradigm, that requeries action and perception. Also, for more information check the OFC to AIF in my notes. Explicitly, key formal path from optimal control to active inference, with schemes that I should include in this review with my own touch, and could be linked to the understanding of inside-out adaptive control loop. \textbf{Optimal control} can be cast as active inference with three simplifications: the first formulates optimal control in terms of predictive coding, the second replaces optimal control with motor reflex arcs, and the third replaces value functions with prior beliefs. The first simplification provides a unifying perspective on perception and action and highlights the central role of Bayesian filtering in model inversion. Furthermore, it shows that forward models in motor control are not the generative models that are actually inverted. The second simplification finesses the problem of delays in descending signals and reinstates classical reflex arcs as an integral part of motor control. Finally, the replacement of value and cost functions with prior beliefs about movements removes the optimal control problem completely. | V3: Original (.bib) | W3: 0.3 | X3: 0.4 | Y3: 0.65 | Z3: 0.55 | AA3: =FALSE() -> FALSE | AB3: theory/review | AC3: 0.312 | AD3: 0.625 | AE3: 0 | AF3: 0.062 | AG3: 0 | AH3: 0 | AI3: 0 | AJ3: 0 | AK3: AIF | AS3: AIF | BF3: no | BH3: not a paradigm / not reached | BI3: theory, review, model or record with no recoverable design
A4: pezzato2020novel | B4: Pezzato, Ferrari & Corbato | C4: 2020 | D4: A novel adaptive controller for robot manipulators based on active inference | E4: AIF | F4: Robotics / engineering control | G4: Robotics / simulation | H4: Computational / N-A | J4: Modelling / simulation | K4: Free-energy / active inference | M4: Derives an adaptive robot-manipulator controller from active inference. | N4: 2 Control frameworks | O4: IEEE Robotics and Automation Letters | Q4: Read | S4: 5 | T4: Core for the Surprise-evoked disruptions paper and model (same implementation of continuous AIF for the tracking module with joint angles and arm's length instead of fixed point mass) | U4: More adaptive controllers for robot manipulators are needed, which can deal with large model uncertainties. This letter presents a novel active inference controller (AIC) as an adaptive control scheme for industrial robots. This scheme is easily scalable to high degrees-of-freedom, and it maintains high performance even in the presence of large unmodeled dynamics. The proposed method is based on active inference, a promising neuroscientific theory of the brain, which describes a biologically plausible al- gorithm for perception and action. In this work, we formulate active inference from a control perspective, deriving a model-free control law which is less sensitive to unmodeled dynamics. The performance and the adaptive properties of the algorithm are compared to a state-of-the-art model reference adaptive controller (MRAC) in an experimental setup with a real 7-DOF robot arm. The results showed that the AIC outperformed the MRAC in terms of adaptability, providing a more general control law. This confirmed the relevance of active inference for robot control. | V4: Original (.bib) | W4: 0.81 | X4: 0.75 | Y4: 0.42 | Z4: 0.8 | AA4: =FALSE() -> FALSE | AB4: simulation | AC4: 0.239 | AD4: 0.435 | AE4: 0.043 | AF4: 0.109 | AG4: 0.043 | AH4: 0.043 | AI4: 0.043 | AJ4: 0.043 | AK4: AIF | BF4: no | BH4: not a paradigm / not reached | BI4: theory, review, model or record with no recoverable design
A5: friston2016active | B5: Friston et al. | C5: 2016 | D5: Active inference and learning | E5: AIF | F5: Active inference / free energy | G5: Review | H5: Theoretical | J5: Review / theory | K5: Free-energy / active inference | M5: Develops active inference as a unified account of perception, action and learning. | N5: 2 Control frameworks | O5: Neuroscience & Biobehavioral Reviews | S5: 3 | V5: Original (.bib) | W5: 0.3 | X5: 0.4 | Y5: 0.65 | Z5: 0.55 | AA5: =FALSE() -> FALSE | AB5: theory/review | AC5: 0.312 | AD5: 0.625 | AE5: 0 | AF5: 0.062 | AG5: 0 | AH5: 0 | AI5: 0 | AJ5: 0 | AK5: AIF | BF5: no | BH5: not a paradigm / not reached | BI5: theory, review, model or record with no recoverable design
A6: friston2017active | B6: Friston et al. | C6: 2017 | D6: Active inference: a process theory | E6: AIF | F6: Active inference / free energy | G6: Theory / conceptual | H6: Theoretical | J6: Theory | K6: Free-energy / active inference | M6: Formalises active inference as a process theory linking free-energy minimisation to neuronal message passing. | N6: 2 Control frameworks | O6: Neural computation | S6: 5 | V6: Original (.bib) | W6: 0.3 | X6: 0.4 | Y6: 0.65 | Z6: 0.55 | AA6: =FALSE() -> FALSE | AB6: theory/review | AC6: 0.312 | AD6: 0.625 | AE6: 0 | AF6: 0.062 | AG6: 0 | AH6: 0 | AI6: 0 | AJ6: 0 | AK6: AIF | BF6: no | BH6: not a paradigm / not reached | BI6: theory, review, model or record with no recoverable design
A7: friston2010free | B7: Friston | C7: 2010 | D7: The free-energy principle: a unified brain theory? | E7: AIF | F7: Active inference / free energy | G7: Review | H7: Theoretical | J7: Review / theory | K7: Free-energy / active inference | M7: Proposes the free-energy principle as a unifying theory of brain function. | N7: 2 Control frameworks | O7: Nature reviews neuroscience | S7: 5 | T7: Core of AIF framework | V7: Original (.bib) | W7: 0.3 | X7: 0.4 | Y7: 0.65 | Z7: 0.55 | AA7: =FALSE() -> FALSE | AB7: theory/review | AC7: 0.312 | AD7: 0.625 | AE7: 0 | AF7: 0.062 | AG7: 0 | AH7: 0 | AI7: 0 | AJ7: 0 | AK7: AIF | BF7: no | BH7: not a paradigm / not reached | BI7: theory, review, model or record with no recoverable design
A8: parr2022active | B8: Parr, Pezzulo & Friston | C8: 2022 | D8: Active inference: the free energy principle in mind, brain, and behavior | E8: AIF | F8: Active inference / free energy | G8: Book | H8: Theoretical | J8: Review / theory | K8: Free-energy / active inference | M8: Textbook synthesis of active inference and the free-energy principle. | N8: 2 Control frameworks | O8: MIT Press | Q8: Read | S8: 5 | T8: Core book of AIF framework and theory, mostly theoretical, really nice examples and intuition ideas to begin with (for more information check my notes from the beginning) | V8: Original (.bib) | W8: 0.3 | X8: 0.4 | Y8: 0.65 | Z8: 0.55 | AA8: =FALSE() -> FALSE | AB8: theory/review | AC8: 0.312 | AD8: 0.625 | AE8: 0 | AF8: 0.062 | AG8: 0 | AH8: 0 | AI8: 0 | AJ8: 0 | AK8: AIF | BF8: no | BH8: not a paradigm / not reached | BI8: theory, review, model or record with no recoverable design
A9: parr2018discrete | B9: Parr & Friston | C9: 2018 | D9: The discrete and continuous brain: from decisions to movement—and back again | E9: AIF | F9: Active inference / free energy | G9: Theory / conceptual | H9: Theoretical | J9: Theory | K9: Free-energy / active inference | M9: Links discrete (decision) and continuous (movement) inference within a hierarchical active-inference scheme. | N9: 2 Control frameworks | O9: Neural computation | Q9: To read | S9: 5 | T9: Might need to go over this one regarding the hierarchical discrete-cont model of the paper | V9: Original (.bib) | W9: 0.3 | X9: 0.4 | Y9: 0.65 | Z9: 0.55 | AA9: =FALSE() -> FALSE | AB9: theory/review | AC9: 0.312 | AD9: 0.625 | AE9: 0 | AF9: 0.062 | AG9: 0 | AH9: 0 | AI9: 0 | AJ9: 0 | AK9: AIF | BF9: no | BH9: not a paradigm / not reached | BI9: theory, review, model or record with no recoverable design
A10: friston2008hierarchical | B10: Friston | C10: 2008 | D10: Hierarchical models in the brain | E10: AIF | F10: Active inference / free energy | G10: Theory / conceptual | H10: Theoretical | J10: Theory | K10: Free-energy / active inference | M10: Frames hierarchical generative models as the substrate for perceptual inference in cortex. | N10: 2 Control frameworks | O10: PLoS computational biology | Q10: To read | S10: 3 | V10: Original (.bib) | W10: 0.3 | X10: 0.4 | Y10: 0.65 | Z10: 0.55 | AA10: =FALSE() -> FALSE | AB10: theory/review | AC10: 0.312 | AD10: 0.625 | AE10: 0 | AF10: 0.062 | AG10: 0 | AH10: 0 | AI10: 0 | AJ10: 0 | AK10: AIF | BF10: no | BH10: not a paradigm / not reached | BI10: theory, review, model or record with no recoverable design
A11: friston2023free | B11: Friston et al. | C11: 2023 | D11: The free energy principle made simpler but not too simple | E11: AIF | F11: Active inference / free energy | G11: Review | H11: Theoretical | J11: Review / theory | K11: Free-energy / active inference | M11: Provides an accessible re-derivation of the free-energy principle and its assumptions. | N11: 2 Control frameworks | O11: Physics Reports | Q11: Read | S11: 3 | T11: free energy principle formulation, from the mathematical and physical foundations to the intuition and applications (in a way that Friston may think is intuitive and smooth to follow but questionable for most of the readers, me included indeed, he has a tendency of not entirely explaining the equations and formulas that annoys also mathematicians). | V11: Original (.bib) | W11: 0.3 | X11: 0.4 | Y11: 0.65 | Z11: 0.55 | AA11: =FALSE() -> FALSE | AB11: theory/review | AC11: 0.312 | AD11: 0.625 | AE11: 0 | AF11: 0.062 | AG11: 0 | AH11: 0 | AI11: 0 | AJ11: 0 | AK11: AIF | BF11: no | BH11: not a paradigm / not reached | BI11: theory, review, model or record with no recoverable design
A12: friston2014active | B12: Friston | C12: 2014 | D12: Active inference and agency | E12: AIF | F12: Active inference / free energy | G12: Theory / conceptual | H12: Theoretical | J12: Theory | K12: Free-energy / active inference | M12: Short conceptual piece connecting active inference to agency. | N12: 2 Control frameworks | O12: Cognitive Neuroscience | S12: 4 | T12: Important for the agency link with Haggard | V12: Original (.bib) | W12: 0.3 | X12: 0.4 | Y12: 0.65 | Z12: 0.55 | AA12: =FALSE() -> FALSE | AB12: theory/review | AC12: 0.312 | AD12: 0.625 | AE12: 0 | AF12: 0.062 | AG12: 0 | AH12: 0 | AI12: 0 | AJ12: 0 | AK12: AIF | BF12: no | BH12: not a paradigm / not reached | BI12: theory, review, model or record with no recoverable design
A13: pezzulo2024active | B13: Pezzulo, Parr & Friston | C13: 2024 | D13: Active inference as a theory of sentient behavior | E13: AIF | F13: Active inference / free energy | G13: Review | H13: Theoretical | J13: Review / theory | K13: Free-energy / active inference | M13: Frames active inference as a general theory of sentient, goal-directed behaviour. | N13: 2 Control frameworks | O13: Biological Psychology | Q13: Read | S13: 5 | T13: Quite core on the computational part, presents a really complete review on Active Inference, that shares a lot of points with our own review, i.e. active inference provides a normative perspective that unifies and advances the predictive and enactive views of brain and behaviour (formalizes inside-out view). | V13: Original (.bib) | W13: 0.3 | X13: 0.4 | Y13: 0.65 | Z13: 0.55 | AA13: =FALSE() -> FALSE | AB13: theory/review | AC13: 0.312 | AD13: 0.625 | AE13: 0 | AF13: 0.062 | AG13: 0 | AH13: 0 | AI13: 0 | AJ13: 0 | AK13: AIF | BF13: no | BH13: not a paradigm / not reached | BI13: theory, review, model or record with no recoverable design
A14: fogassi2004action | B14: Fogassi & Gallese | C14: 2004 | D14: Action as a binding key to multisensory integration | E14: AIF | F14: Perception-action & multisensory | G14: Theory / conceptual | H14: Theoretical | J14: Theory | K14: Ecological / dynamical | M14: Proposes action as the organising principle that binds multisensory signals. | N14: 6 Corollary discharge & agency | S14: 2 | V14: Original (.bib) | W14: 0.45 | X14: 0.48 | Y14: 0.42 | Z14: 0.5 | AA14: =FALSE() -> FALSE | AB14: theory/review | AC14: 0 | AD14: 0 | AE14: 0.107 | AF14: 0.143 | AG14: 0 | AH14: 0.679 | AI14: 0.071 | AJ14: 0 | AK14: AC | BF14: no | BH14: not a paradigm / not reached | BI14: theory, review, model or record with no recoverable design
A15: pezzulo2011should | B15: Pezzulo & Dindo | C15: 2011 | D15: What should I do next? Using shared representations to solve interaction problems | E15: AIF | F15: Action selection & affordance competition | G15: Theory / conceptual | H15: Theoretical | J15: Theory | K15: Free-energy / active inference | M15: Uses shared representations to explain how agents solve interaction / joint-action problems. | N15: 3 Decision & action | O15: Experimental Brain Research | S15: 3 | V15: Original (.bib) | W15: 0.62 | X15: 0.5 | Y15: 0.42 | Z15: 0.68 | AA15: =FALSE() -> FALSE | AB15: theory/review | AC15: 0.196 | AD15: 0.391 | AE15: 0.043 | AF15: 0.065 | AG15: 0.043 | AH15: 0.261 | AI15: 0 | AJ15: 0 | AK15: AIF | BF15: no | BH15: not a paradigm / not reached | BI15: theory, review, model or record with no recoverable design
A16: pezzulo2016navigating | B16: Pezzulo & Cisek | C16: 2016 | D16: Navigating the affordance landscape: feedback control as a process model of behavior and cognition | E16: AIF | F16: Action selection & affordance competition | G16: Review | H16: Theoretical | J16: Review / theory | K16: Affordance competition | M16: Casts feedback control over an affordance landscape as a process model of behaviour and cognition. | N16: 3 Decision & action | O16: Trends in cognitive sciences | Q16: Read | S16: 5 | T16: Review on adaptive behaviour and formalization of the action-perception loop as a hierarchical control model (really really related to everything I am reading and assessing on the literature review in fact). It also presents these hierarchical structures, with low levels (more related to the motor output of the action and proprioceptive feedback) and high levels (with more abstract goals and long term target choices). Amazing cross-over between Giovanni and Paul to be honest. | V16: Original (.bib) | W16: 0.67 | X16: 0.55 | Y16: 0.32 | Z16: 0.73 | AA16: =FALSE() -> FALSE | AB16: theory/review | AC16: 0 | AD16: 0 | AE16: 0.125 | AF16: 0 | AG16: 0.125 | AH16: 0.75 | AI16: 0 | AJ16: 0 | AK16: AC | BF16: no | BH16: not a paradigm / not reached | BI16: theory, review, model or record with no recoverable design
A17: Heins2022 | B17: Heins et al. | C17: 2022 | D17: pymdp: A Python library for active inference in discrete state spaces | E17: AIF | F17: Methods / tools | G17: Methods / tools | H17: Computational / N-A | J17: Software | K17: Free-energy / active inference | M17: Presents pymdp, a Python library for discrete-state active inference. | N17: Methods / appendix | O17: Journal of Open Source Software | P17: https://doi.org/10.21105/joss.04098 | S17: 3 | V17: Original (.bib) | W17: 0.1 | X17: 0.1 | Y17: 0.2 | Z17: 0.5 | AA17: =FALSE() -> FALSE | AB17: theory/review | AC17: 0.239 | AD17: 0.435 | AE17: 0.043 | AF17: 0.109 | AG17: 0.043 | AH17: 0.043 | AI17: 0.043 | AJ17: 0.043 | AK17: AIF | BF17: no | BH17: not a paradigm / not reached | BI17: theory, review, model or record with no recoverable design
A18: baioumy2022unbiased | B18: Baioumy et al. | C18: 2022 | D18: Unbiased active inference for classical control | E18: AIF | F18: Robotics / engineering control | G18: Robotics / simulation | H18: Computational / N-A | J18: Modelling / simulation | K18: Free-energy / active inference | M18: Gives an unbiased active-inference formulation for classical control problems. | N18: 2 Control frameworks | O18: 2022 IEEE/RSJ International Conference on Intelligent Robots and Systems (IROS) | Q18: Read | S18: 4 | T18: AIF continuous tracking model implemented with joint angles | U18: Active inference is a mathematical framework that originated in computational neuroscience. Recently, it has been demonstrated as a promising approach for constructing goal-driven behavior in robotics. Specifically, the active inference controller (AIC) has been successful on several continuous control and state-estimation tasks. Despite its relative success, some established design choices lead to a number of practical limitations for robot control. These include having a biased estimate of the state, and only an implicit model of control actions. In this paper, we highlight these limitations and propose an extended version of the unbiased active inference controller (u-AIC). The u-AIC maintains all the compelling benefits of the AIC and removes its limitations. Simulation results on a 2-DOF arm and experiments on a real 7-DOF manipulator show the improved performance of the u-AIC with respect to the standard AIC. | V18: Original (.bib) | W18: 0.81 | X18: 0.75 | Y18: 0.42 | Z18: 0.8 | AA18: =FALSE() -> FALSE | AB18: simulation | AC18: 0.239 | AD18: 0.435 | AE18: 0.043 | AF18: 0.109 | AG18: 0.043 | AH18: 0.043 | AI18: 0.043 | AJ18: 0.043 | AK18: AIF | BF18: no | BH18: not a paradigm / not reached | BI18: theory, review, model or record with no recoverable design
A19: priorelli2023deep | B19: Priorelli, Pezzulo & Stoianov | C19: 2023 | D19: Deep kinematic inference affords efficient and scalable control of bodily movements | E19: AIF | F19: Active inference / free energy | G19: Computational model | H19: Computational / N-A | J19: Modelling / simulation | K19: Free-energy / active inference | M19: Introduces deep kinematic active inference for scalable control of bodily movement. | N19: 2 Control frameworks | O19: Proceedings of the National Academy of Sciences | Q19: Read | S19: 3 | T19: Deep model for AIF hierarchical implementation | V19: Original (.bib) | W19: 0.3 | X19: 0.45 | Y19: 0.7 | Z19: 0.55 | AA19: =FALSE() -> FALSE | AB19: simulation | AC19: 0.312 | AD19: 0.625 | AE19: 0 | AF19: 0.062 | AG19: 0 | AH19: 0 | AI19: 0 | AJ19: 0 | AK19: AIF | BF19: no | BH19: not a paradigm / not reached | BI19: theory, review, model or record with no recoverable design
A20: bufacchi2018action | B20: Bufacchi & Iannetti | C20: 2018 | D20: An action field theory of peripersonal space | E20: Action control | F20: Peripersonal space & defence | G20: Theory / conceptual | H20: Human | J20: Review / theory | K20: Peripersonal space / action fields | M20: Reframes peripersonal space as continuous action-value fields rather than a bounded zone. | N20: 5 Saliency to action | O20: Trends in cognitive sciences | Q20: Read | S20: 4 | V20: Original (.bib) | W20: 0.4 | X20: 0.35 | Y20: 0.55 | Z20: 0.15 | AA20: =FALSE() -> FALSE | AB20: theory/review | AC20: 0 | AD20: 0 | AE20: 0 | AF20: 0 | AG20: 0 | AH20: 0.571 | AI20: 0.429 | AJ20: 0 | AK20: AC | BF20: no | BH20: not a paradigm / not reached | BI20: theory, review, model or record with no recoverable design
A21: todd1849pathology | B21: Todd, Robert Bentley | C21: 1849 | D21: On the pathology and treatment of convulsive diseases. | E21: Action control | F21: Motor cortex & body maps | G21: NHP electrophysiology | H21: Human | J21: Microstimulation | K21: General / foundational | M21: First stimulation study on the cortex to study the underlying mechanisms of movements | N21: 7 Foundations | O21: British medical journal | S21: 2 | T21: Todd (1849) attempted to define the brain regions that caused epilepsy. His evidence for midbrain involvement was that, when he electrically stimulated the midbrains of rabbits, he evoked general convul- sions that resembled epilepsy. odd suggested a three-part mechanism: malfunction of the cerebral cortex was responsible solely for the loss of consciousness and higher mental functions during epilepsy; malfunction of the midbrain was responsible for the motoric convulsions; and malfunction of the spinal cord and medulla was uncommon and resulted in sustained muscle contractions rather than epileptic seizures. Todd came remarkably close to deducing the motor functions of the cortex. | V21: From Grazziano | W21: 0.65 | X21: 0.4 | Y21: 0.1 | Z21: 0.75 | AA21: =TRUE() -> TRUE | AB21: empirical | AC21: 0.088 | AD21: 0.088 | AE21: 0.265 | AF21: 0.088 | AG21: 0.088 | AH21: 0.206 | AI21: 0.088 | AJ21: 0.088 | AK21: OFC | BF21: no | BH21: rule R6 | BI21: clinical / lesion series (R6)
A22: bufacchi2023cortico | B22: Bufacchi et al. | C22: 2023 | D22: Cortico-spinal modularity in the parieto-frontal system: A new perspective on action control | E22: Action control | F22: Motor cortex & body maps | G22: Review | H22: Multiple / cross-species | J22: Review / theory | K22: Peripersonal space / action fields | M22: Proposes cortico-spinal modularity in parieto-frontal circuits as a framework for action control. | N22: 7 Foundations | O22: Progress in neurobiology | Q22: Read | S22: 4 | T22: Review that argues that multiple parieto-frontal spinal command modules that can bypass MI. Five observations support this modular perspective: (i) the statistics of cortical connectivity demonstrate functionally- related clusters of cortical areas, defining functional modules in the premotor, cingulate, and parietal cortices; (ii) different corticospinal pathways originate from the above areas, each with a distinct range of conduction velocities; (iii) the activation time of each module varies depending on task, and different modules can be activated simultaneously; (iv) a modular architecture with direct motor output is faster and less metabolically expensive than an architecture that relies on MI, given the slow connections between MI and other cortical areas; (v) lesions of the areas composing parieto-frontal modules have different effects from lesions of MI. Interesting reference also for other areas involved in movement other than M1 (for literature review). Even has more references | V22: Original (.bib) | W22: 0.6 | X22: 0.4 | Y22: 0.15 | Z22: 0.6 | AA22: =FALSE() -> FALSE | AB22: theory/review | AC22: 0 | AD22: 0 | AE22: 0.194 | AF22: 0 | AG22: 0 | AH22: 0.516 | AI22: 0.29 | AJ22: 0 | AK22: AC | BF22: no | BH22: not a paradigm / not reached | BI22: theory, review, model or record with no recoverable design
A23: broca1861remarks | B23: Broca, Paul and others | C23: 1861 | D23: Remarks on the seat of the faculty of articulated language, following an observation of aphemia (loss of speech) | E23: Action control | F23: Motor cortex & body maps | G23: NHP electrophysiology | H23: Human | J23: Autopsy | K23: General / foundational | M23: Studies on Tan (human with loss of speech) | N23: 7 Foundations | O23: British medical journal | S23: 2 | T23: Broca examined the autopsy from Tan's brain once he died from an infection, and he noticed that the left frontal lobe was badly degenerated with a focus of degeneration in the third frontal convolution, now commonly known as Broca’s area. He was really close to deducing the motor map, sicne he willing to infer that at least one function, speech, was localized to a region of the cerebral cortex. Yet in his words, “Everybody knows that the cerebral convolutions are not motor organs.", which kept him from making stronger claims and challenge his contemporaneous researchers. | V23: From Grazziano | W23: 0.65 | X23: 0.4 | Y23: 0.1 | Z23: 0.75 | AA23: =TRUE() -> TRUE | AB23: empirical | AC23: 0.088 | AD23: 0.088 | AE23: 0.265 | AF23: 0.088 | AG23: 0.088 | AH23: 0.206 | AI23: 0.088 | AJ23: 0.088 | AK23: OFC | BF23: no | BH23: rule R6 | BI23: autopsy case study (R6)
A24: sechenov1965reflexes | B24: Sechenov, Ivan M. | C24: 1863 | D24: Reflexes of the Brain | E24: Motor control | M24: All the infinite diversity of the external manifestations of brain activity is ultimately reduced to a single phenomenon—muscular movement | W24: 0.4 | X24: 0.4 | Y24: 0.35 | Z24: 0.5 | AA24: =TRUE() -> TRUE | AB24: empirical | AC24: 0.125 | AD24: 0.125 | AE24: 0.125 | AF24: 0.125 | AG24: 0.125 | AH24: 0.125 | AI24: 0.125 | AJ24: 0.125 | AK24: PC | BF24: no | BH24: rule R6 | BI24: book
A25: bufacchi2021peripersonal | B25: Bufacchi & Iannetti | C25: 2021 | D25: What do ‘peripersonal space measures’ really reflect? The action field perspective | E25: Action control | F25: Peripersonal space & defence | G25: Theory / conceptual | H25: Human | J25: Review / theory | K25: Peripersonal space / action fields | M25: Argues peripersonal-space measures reflect action fields rather than a single space. | N25: 5 Saliency to action | O25: The World at Our Fingertips: A Multidisciplinary Exploration of Peripersonal Space | S25: 3 | V25: Original (.bib) | W25: 0.4 | X25: 0.35 | Y25: 0.55 | Z25: 0.15 | AA25: =FALSE() -> FALSE | AB25: theory/review | AC25: 0 | AD25: 0 | AE25: 0 | AF25: 0 | AG25: 0 | AH25: 0.571 | AI25: 0.429 | AJ25: 0 | AK25: AC | BF25: no | BH25: not a paradigm / not reached | BI25: theory, review, model or record with no recoverable design
A26: fritsch1870electrical | B26: Fritsch, Gustav and Hitzig, Eduard | C26: 1870 | D26: On the electrical excitability of the cerebrum | E26: Action control | F26: Motor cortex & body maps | G26: NHP electrophysiology | H26: Non-human primate/dogs | J26: Microstimulation | K26: General / foundational | M26: First homunculus on dogs | N26: 7 Foundations | O26: British medical journal | S26: 2 | T26: Fritsch and Hitzig’s initial discovery of motor cortex | V26: From Grazziano | W26: 0.65 | X26: 0.4 | Y26: 0.1 | Z26: 0.75 | AA26: =TRUE() -> TRUE | AB26: empirical | AC26: 0.088 | AD26: 0.088 | AE26: 0.265 | AF26: 0.088 | AG26: 0.088 | AH26: 0.206 | AI26: 0.088 | AJ26: 0.088 | AK26: OFC | BF26: no | BH26: rule R6 | BI26: stimulation mapping (R6)
A27: bufacchi2018understanding | B27: Bufacchi | C27: 2018 | D27: Understanding defensive peripersonal space through mathematical modelling | E27: Action control | F27: Peripersonal space & defence | G27: Thesis | H27: Human | J27: Modelling + behavioural | K27: Peripersonal space / action fields | M27: Doctoral thesis on mathematical modelling of defensive peripersonal space. | N27: 5 Saliency to action | O27: UCL (University College London) | S27: 2 | V27: Original (.bib) | W27: 0.4 | X27: 0.35 | Y27: 0.55 | Z27: 0.15 | AA27: =FALSE() -> FALSE | AB27: theory/review | AC27: 0 | AD27: 0 | AE27: 0 | AF27: 0 | AG27: 0 | AH27: 0.571 | AI27: 0.429 | AJ27: 0 | AK27: AC | BF27: no | BH27: not a paradigm / not reached | BI27: theory, review, model or record with no recoverable design
A28: jackson1870study | B28: Jackson, John Hughlings | C28: 1870 | D28: A study of convulsions | E28: Action control | F28: Motor cortex & body maps | G28: NHP electrophysiology | H28: Human | J28: Autopsy | K28: General / foundational | M28: Studies on epiletpic humans. He formulated one general principle of brain organization that behaviorally important functions have physically larger representations. He also deduced that the brain contained different centers for the control of different body parts. | N28: 7 Foundations | O28: British medical journal | S28: 2 | T28: Jackson implied that the partial seizures, being simpler, were probably caused by the striatum, whereas the global seizures, being more complex, may have been caused by the cortex. Jackson described damage to the cerebral cortex, not to the striatum; yet he seemed unable to let go of the idea that the cortex was too complex a structure for the control of a body part. He formulated one general principle of brain organization that behaviorally important functions have physically larger representations. | V28: From Grazziano | W28: 0.65 | X28: 0.4 | Y28: 0.1 | Z28: 0.75 | AA28: =TRUE() -> TRUE | AB28: empirical | AC28: 0.088 | AD28: 0.088 | AE28: 0.265 | AF28: 0.088 | AG28: 0.088 | AH28: 0.206 | AI28: 0.088 | AJ28: 0.088 | AK28: OFC | BF28: no | BH28: rule R6 | BI28: clinical / lesion series (R6)
A29: ferrier1873experimental | B29: Ferrier, David | C29: 1873 | D29: Experimental researches in cerebral physiology and pathology | E29: Action control | F29: Motor cortex & body maps | G29: NHP electrophysiology | H29: Non-human primate/dogs | J29: Microstimulation | K29: General / foundational | M29: Shows electrical stimulation evokes coordinated arm movements toward spatial postures. First muscle activation map to repertoire of movements. | N29: 7 Foundations | O29: British medical journal | S29: 2 | T29: Ferrier (1873) replicated the results from Fritsch and Hitzig’s initial discovery of motor cortex and extended them from dogs to cats, rabbits, and guinea pigs, though he was unable to evoke movements from the brains of birds, complaining that they were too soft and oozed when stimulated. In Ferrier’s view (1873, 1874), the shorter stimulation missed essential movements, | V29: From Grazziano | W29: 0.65 | X29: 0.4 | Y29: 0.1 | Z29: 0.75 | AA29: =TRUE() -> TRUE | AB29: empirical | AC29: 0.088 | AD29: 0.088 | AE29: 0.265 | AF29: 0.088 | AG29: 0.088 | AH29: 0.206 | AI29: 0.088 | AJ29: 0.088 | AK29: OFC | BF29: no | BH29: rule R6 | BI29: stimulation mapping (R6)
A30: de2015many | B30: de Vignemont & Iannetti | C30: 2015 | D30: How many peripersonal spaces? | E30: Action control | F30: Peripersonal space & defence | G30: Review | H30: Human | J30: Review / theory | K30: Peripersonal space / action fields | M30: Questions whether there is a single peripersonal space, distinguishing multiple functional spaces. | N30: 5 Saliency to action | O30: Neuropsychologia | S30: 2 | V30: Original (.bib) | W30: 0.4 | X30: 0.35 | Y30: 0.55 | Z30: 0.15 | AA30: =FALSE() -> FALSE | AB30: theory/review | AC30: 0 | AD30: 0 | AE30: 0 | AF30: 0 | AG30: 0 | AH30: 0.571 | AI30: 0.429 | AJ30: 0 | AK30: AC | BF30: no | BH30: not a paradigm / not reached | BI30: theory, review, model or record with no recoverable design
A31: braitenberg1986vehicles | B31: Braitenberg | C31: 1986 | D31: Vehicles: Experiments in synthetic psychology | E31: Action control | F31: Foundational / historical | G31: Book | H31: Theoretical | J31: Theory | K31: Ecological / dynamical | M31: Uses synthetic vehicles to show complex behaviour from simple sensorimotor couplings. | N31: 1 Introduction | O31: MIT press | S31: 3 | V31: Original (.bib) | W31: 0.22 | X31: 0.4 | Y31: 0.32 | Z31: 0.5 | AA31: =FALSE() -> FALSE | AB31: theory/review | AC31: 0.083 | AD31: 0 | AE31: 0.208 | AF31: 0.083 | AG31: 0 | AH31: 0.625 | AI31: 0 | AJ31: 0 | AK31: AC | BF31: no | BH31: not a paradigm / not reached | BI31: theory, review, model or record with no recoverable design
A32: james1890principles | B32: James | C32: 1890 | D32: The principles of psychology | E32: Action control | F32: Foundational / historical | G32: Historical / foundational | H32: Theoretical | J32: Theory | K32: General / foundational | M32: Foundational text of scientific psychology. | N32: 1 Introduction | O32: Henry Holt | S32: 1 | V32: Original (.bib) | W32: 0.22 | X32: 0.32 | Y32: 0.32 | Z32: 0.5 | AA32: =FALSE() -> FALSE | AB32: theory/review | AC32: 0.167 | AD32: 0.1 | AE32: 0.167 | AF32: 0.167 | AG32: 0.1 | AH32: 0.1 | AI32: 0.1 | AJ32: 0.1 | AK32: PC | BF32: no | BH32: rule R6 | BI32: book / foundational text
A33: graziano2008intelligent | B33: Graziano | C33: 2008 | D33: The intelligent movement machine: An ethological perspective on the primate motor system | E33: Action control | F33: Motor cortex & body maps | G33: Book | H33: Non-human primate | J33: Review / theory | K33: General / foundational | M33: Presents an ethological view of motor cortex as organised around meaningful actions. | N33: 7 Foundations | O33: Oxford University Press | S33: 2 | V33: From Grazziano | W33: 0.6 | X33: 0.4 | Y33: 0.1 | Z33: 0.7 | AA33: =FALSE() -> FALSE | AB33: theory/review | AC33: 0.088 | AD33: 0.088 | AE33: 0.265 | AF33: 0.088 | AG33: 0.088 | AH33: 0.206 | AI33: 0.088 | AJ33: 0.088 | AK33: OFC | BF33: no | BH33: not a paradigm / not reached | BI33: theory, review, model or record with no recoverable design
A34: murray2017evolution | B34: Murray, Wise & Graham | C34: 2017 | D34: the Evolution of Memory Systems: Ancestors, anatomy, and adaptations | E34: Action control | F34: Foundational / historical | G34: Book | H34: Multiple / cross-species | J34: Review / theory | K34: General / foundational | M34: Provides a comparative-evolutionary account of memory systems. | N34: 1 Introduction | O34: Oxford university press | S34: 1 | V34: Original (.bib) | W34: 0.22 | X34: 0.32 | Y34: 0.32 | Z34: 0.5 | AA34: =FALSE() -> FALSE | AB34: theory/review | AC34: 0.167 | AD34: 0.1 | AE34: 0.167 | AF34: 0.167 | AG34: 0.1 | AH34: 0.1 | AI34: 0.1 | AJ34: 0.1 | AK34: PC | BF34: no | BH34: not a paradigm / not reached | BI34: theory, review, model or record with no recoverable design
A35: graziano2006parieto | B35: Graziano & Cooke | C35: 2006 | D35: Parieto-frontal interactions, personal space, and defensive behavior | E35: Action control | F35: Peripersonal space & defence | G35: Review | H35: Non-human primate | J35: Review (microstimulation) | K35: Peripersonal space / action fields | M35: Reviews parieto-frontal circuits underlying personal space and defensive behaviour. | N35: 5 Saliency to action | O35: Neuropsychologia | S35: 3 | V35: From Grazziano | W35: 0.4 | X35: 0.35 | Y35: 0.55 | Z35: 0.15 | AA35: =FALSE() -> FALSE | AB35: theory/review | AC35: 0 | AD35: 0 | AE35: 0 | AF35: 0 | AG35: 0 | AH35: 0.571 | AI35: 0.429 | AJ35: 0 | AK35: AC | BF35: no | BH35: not a paradigm / not reached | BI35: theory, review, model or record with no recoverable design
A36: sperry1950neural | B36: Sperry | C36: 1950 | D36: Neural basis of the spontaneous optokinetic response produced by visual inversion. | E36: Action control | F36: Corollary discharge / efference copy | G36: Historical / foundational | H36: Multiple / cross-species | J36: Behavioural | K36: Predictive coding / corollary discharge | M36: Introduces the concept of corollary discharge from visual-inversion experiments. | N36: 6 Corollary discharge & agency | O36: Journal of comparative and physiological psychology | S36: 3 | V36: Original (.bib) | W36: 0.5 | X36: 0.42 | Y36: 0.35 | Z36: 0.95 | AA36: =FALSE() -> FALSE | AB36: theory/review | AC36: 0.718 | AD36: 0.205 | AE36: 0 | AF36: 0.077 | AG36: 0 | AH36: 0 | AI36: 0 | AJ36: 0 | AK36: PC | AL36: 0 | AM36: 1 | AN36: 0.67 | AO36: 1 | AP36: 0.83 | AQ36: 0 | AR36: 0.57 | BF36: yes | BG36: lo | BH36: this pass | BI36: surgical inversion of the eye: a sustained, purely endogenous mismatch in a free-swimming animal | BJ36: 1
A37: ferrier1875experiments | B37: Ferrier, David | C37: 1875 | D37: Experiments on the brain of monkeys | E37: Action control | F37: Motor cortex & body maps | G37: NHP electrophysiology | H37: Non-human primate/dogs | J37: Microstimulation | K37: General / foundational | M37: Shows electrical stimulation evokes coordinated arm movements toward spatial postures. First muscle activation map to repertoire of movements. | N37: 7 Foundations | O37: British medical journal | S37: 2 | V37: From Grazziano | W37: 0.65 | X37: 0.4 | Y37: 0.1 | Z37: 0.75 | AA37: =TRUE() -> TRUE | AB37: empirical | AC37: 0.088 | AD37: 0.088 | AE37: 0.265 | AF37: 0.088 | AG37: 0.088 | AH37: 0.206 | AI37: 0.088 | AJ37: 0.088 | AK37: OFC | BF37: no | BH37: rule R6 | BI37: stimulation mapping (R6)
A38: jackson1875anatomical | B38: Jackson, John Hughlings | C38: 1875 | D38: ON THE ANATOMICAL \& PHYSIOLOGICAL LOCALISATION OF MOVEMENTS IN THE BRAIN | E38: Action control | F38: Motor cortex & body maps | G38: NHP electrophysiology | H38: Human | J38: Autopsy | K38: General / foundational | M38: Studies on epileptic humans. He did not accomplish to deduce the cortex mapping. | N38: 7 Foundations | O38: British medical journal | S38: 2 | T38: Jackson, therefore, failed totally to appreciate the true reason for the progression of partial seizures across the body, namely the spread of an epilep- tic storm across a map of the body in the cortex, even after the first cortex mapping published by fritsch1870. | V38: From Grazziano | W38: 0.65 | X38: 0.4 | Y38: 0.1 | Z38: 0.75 | AA38: =TRUE() -> TRUE | AB38: empirical | AC38: 0.088 | AD38: 0.088 | AE38: 0.265 | AF38: 0.088 | AG38: 0.088 | AH38: 0.206 | AI38: 0.088 | AJ38: 0.088 | AK38: OFC | BF38: no | BH38: rule R6 | BI38: clinical / lesion series (R6)
A39: beevor1887vi | B39: Beevor, Charles E and Horsley, Victor Alexander Haden | C39: 1887 | D39: A minute analysis (experiments) of the various movements produced by stimulating in the monkey different regions of the cortical centre for the upper limb, as defined by Professor Ferrier | E39: Action control | F39: Motor cortex & body maps | G39: NHP electrophysiology | H39: Non-human primate/dogs | J39: Microstimulation | K39: General / foundational | M39: First homunculus on dogs | N39: 7 Foundations | O39: British medical journal | S39: 2 | T39: Study focusing on the arm and hand representation in the monkey motor cortex, based on Ferrier's 1873. They outlined a cortical map that was not merely a plan of the body’s muscles but was an arrangement of useful movements. It was the last study on this topic (examine the topographic mapping of complex actions on the motor cortex) before Grazziano's study in 2005. They showed that stimulation of the lower or ventral part of the arm representation tended to evoke movements consistent with bringing an object toward the body, especially toward the mouth for feeding. | V39: From Grazziano | W39: 0.65 | X39: 0.4 | Y39: 0.1 | Z39: 0.75 | AA39: =TRUE() -> TRUE | AB39: empirical | AC39: 0.088 | AD39: 0.088 | AE39: 0.265 | AF39: 0.088 | AG39: 0.088 | AH39: 0.206 | AI39: 0.088 | AJ39: 0.088 | AK39: OFC | BF39: no | BH39: rule R6 | BI39: stimulation mapping (R6)
A40: beevor1890iii | B40: Beevor, Charles E and Horsley, Victor Alexander Haden | C40: 1890 | D40: An experimental investigation into the arrangement of the excitable fibres of the internal capsule of the bonnet monkey (macacus sinicus) | E40: Action control | F40: Motor cortex & body maps | G40: NHP electrophysiology | H40: Non-human primate/dogs | J40: Microstimulation | K40: General / foundational | M40: First homunculus on dogs | N40: 7 Foundations | O40: British medical journal | S40: 2 | T40: This experiment represented a move toward a “muscles” view of motor cortex function and away from a “movements” view. This view of motor cortex was radically different from the view presented in their earlier (Beevor and Horsley, 1887) paper or proposed by Ferrier (1874). They propose instead that there are no motor centers and the function of motor cortex was defined by its descending connections to the spinal cord. This view dominated neuroscience untel grazziano again. | V40: From Grazziano | W40: 0.65 | X40: 0.4 | Y40: 0.1 | Z40: 0.75 | AA40: =TRUE() -> TRUE | AB40: empirical | AC40: 0.088 | AD40: 0.088 | AE40: 0.265 | AF40: 0.088 | AG40: 0.088 | AH40: 0.206 | AI40: 0.088 | AJ40: 0.088 | AK40: OFC | BF40: no | BH40: rule R6 | BI40: stimulation mapping (R6)
...

Sheet Summary
B2: Literature map - summary counts
B3: All counts are live COUNTIF formulas over the Articles sheet. Filter or edit Articles and these update on recalc.
B5: By topic | C5: Count | E5: By study type | F5: Count | H5: By framework | I5: Count | K5: By thematic file | L5: Count
B6: Action selection & affordance competition | C6: =COUNTIF(Articles!$F$2:$F$591,B6) -> 9 | E6: Book | F6: =COUNTIF(Articles!$G$2:$G$591,E6) -> 11 | H6: Affordance competition | I6: =COUNTIF(Articles!$K$2:$K$591,H6) -> 18 | K6: AIF | L6: =COUNTIF(Articles!$E$2:$E$591,K6) -> 38
B7: Anatomical mapping | C7: =COUNTIF(Articles!$F$2:$F$591,B7) -> 2 | E7: Computational model | F7: =COUNTIF(Articles!$G$2:$G$591,E7) -> 21 | H7: Agency / volition | I7: =COUNTIF(Articles!$K$2:$K$591,H7) -> 7 | K7: Action control | L7: =COUNTIF(Articles!$E$2:$E$591,K7) -> 91
B8: Active inference / free energy | C8: =COUNTIF(Articles!$F$2:$F$591,B8) -> 30 | E8: Empirical (neurophysiology) | F8: =COUNTIF(Articles!$G$2:$G$591,E8) -> 2 | H8: Ecological / dynamical | I8: =COUNTIF(Articles!$K$2:$K$591,H8) -> 6 | K8: Decision making | L8: =COUNTIF(Articles!$E$2:$E$591,K8) -> 41
B9: Affordances & ecological psychology | C9: =COUNTIF(Articles!$F$2:$F$591,B9) -> 3 | E9: Empirical (paleontology) | F9: =COUNTIF(Articles!$G$2:$G$591,E9) -> 1 | H9: Free-energy / active inference | I9: =COUNTIF(Articles!$K$2:$K$591,H9) -> 34 | K9: OFC (optimal feedback control) | L9: =COUNTIF(Articles!$E$2:$E$591,K9) -> 35
B10: Biomechanical / effort costs | C10: =COUNTIF(Articles!$F$2:$F$591,B10) -> 7 | E10: Empirical + modelling | F10: =COUNTIF(Articles!$G$2:$G$591,E10) -> 2 | H10: General / foundational | I10: =COUNTIF(Articles!$K$2:$K$591,H10) -> 34 | K10: Saliency | L10: =COUNTIF(Articles!$E$2:$E$591,K10) -> 67
B11: Corollary discharge / efference copy | C11: =COUNTIF(Articles!$F$2:$F$591,B11) -> 8 | E11: Historical / foundational | F11: =COUNTIF(Articles!$G$2:$G$591,E11) -> 33 | H11: Neural dynamics | I11: =COUNTIF(Articles!$K$2:$K$591,H11) -> 5 | K11: Total | L11: =SUM(L6:L10) -> 272
B12: Decisions during movement | C12: =COUNTIF(Articles!$F$2:$F$591,B12) -> 13 | E12: Human EEG/MEG | F12: =COUNTIF(Articles!$G$2:$G$591,E12) -> 31 | H12: Optimal feedback control | I12: =COUNTIF(Articles!$K$2:$K$591,H12) -> 33
B13: Foundational / inside-out | C13: =COUNTIF(Articles!$F$2:$F$591,B13) -> 6 | E13: Human TMS / corticospinal | F13: =COUNTIF(Articles!$G$2:$G$591,E13) -> 9 | H13: Peripersonal space / action fields | I13: =COUNTIF(Articles!$K$2:$K$591,H13) -> 12 | K13: By species / model | L13: Count
B14: Foundational / historical | C14: =COUNTIF(Articles!$F$2:$F$591,B14) -> 4 | E14: Human behaviour / psychophysics | F14: =COUNTIF(Articles!$G$2:$G$591,E14) -> 28 | H14: Predictive coding / corollary discharge | I14: =COUNTIF(Articles!$K$2:$K$591,H14) -> 8 | K14: Computational / N-A | L14: =COUNTIF(Articles!$H$2:$H$591,K14) -> 15
B15: Methods / tools | C15: =COUNTIF(Articles!$F$2:$F$591,B15) -> 9 | E15: Human fMRI | F15: =COUNTIF(Articles!$G$2:$G$591,E15) -> 4 | H15: Salience detection | I15: =COUNTIF(Articles!$K$2:$K$591,H15) -> 79 | K15: Human | L15: =COUNTIF(Articles!$H$2:$H$591,K15) -> 139
B16: Motor cortex & body maps | C16: =COUNTIF(Articles!$F$2:$F$591,B16) -> 21 | E16: Methods / tools | F16: =COUNTIF(Articles!$G$2:$G$591,E16) -> 6 | H16: Statistical decision theory | I16: =COUNTIF(Articles!$K$2:$K$591,H16) -> 11 | K16: Multiple / cross-species | L16: =COUNTIF(Articles!$H$2:$H$591,K16) -> 8
B17: Neural population dynamics | C17: =COUNTIF(Articles!$F$2:$F$591,B17) -> 2 | E17: NHP electrophysiology | F17: =COUNTIF(Articles!$G$2:$G$591,E17) -> 20 | H17: Total | I17: =SUM(I6:I16) -> 247 | K17: N/A | L17: =COUNTIF(Articles!$H$2:$H$591,K17) -> 11
B18: Optimal feedback control | C18: =COUNTIF(Articles!$F$2:$F$591,B18) -> 19 | E18: Review | F18: =COUNTIF(Articles!$G$2:$G$591,E18) -> 69 | K18: Non-human primate | L18: =COUNTIF(Articles!$H$2:$H$591,K18) -> 17
B19: Pain & salience (Iannetti) | C19: =COUNTIF(Articles!$F$2:$F$591,B19) -> 8 | E19: Robotics / simulation | F19: =COUNTIF(Articles!$G$2:$G$591,E19) -> 2 | K19: Rodent | L19: =COUNTIF(Articles!$H$2:$H$591,K19) -> 6
B20: Perception-action & multisensory | C20: =COUNTIF(Articles!$F$2:$F$591,B20) -> 2 | E20: Rodent electrophysiology | F20: =COUNTIF(Articles!$G$2:$G$591,E20) -> 5 | K20: Theoretical | L20: =COUNTIF(Articles!$H$2:$H$591,K20) -> 91
B21: Peripersonal space & defence | C21: =COUNTIF(Articles!$F$2:$F$591,B21) -> 12 | E21: Theory / conceptual | F21: =COUNTIF(Articles!$G$2:$G$591,E21) -> 41 | K21: Total | L21: =SUM(L14:L20) -> 287
B22: Robotics / engineering control | C22: =COUNTIF(Articles!$F$2:$F$591,B22) -> 4 | E22: Thesis | F22: =COUNTIF(Articles!$G$2:$G$591,E22) -> 3
B23: Saliency & attention models | C23: =COUNTIF(Articles!$F$2:$F$591,B23) -> 11 | E23: Total | F23: =SUM(F6:F22) -> 288
B24: Saliency-motor coupling / reactive behaviour | C24: =COUNTIF(Articles!$F$2:$F$591,B24) -> 18
B25: Sense of agency & sensory attenuation | C25: =COUNTIF(Articles!$F$2:$F$591,B25) -> 17
B26: Surprise & novelty | C26: =COUNTIF(Articles!$F$2:$F$591,B26) -> 33
B27: Value & reward-based decision | C27: =COUNTIF(Articles!$F$2:$F$591,B27) -> 11
B28: Vertex potential & evoked potentials | C28: =COUNTIF(Articles!$F$2:$F$591,B28) -> 25
B29: Working memory & executive control | C29: =COUNTIF(Articles!$F$2:$F$591,B29) -> 3
B30: Total | C30: =SUM(C6:C29) -> 277

Sheet Axis scoring
A1: PARADIGM-SPACE AXES & COMPUTATIONAL-ACCOUNT SCORING
A3: These columns are an AUTOMATED first-pass rubric, derived only from the Topic, Study type and Framework columns. Treat them like the Relevance column: a reproducible starting point to verify and overwrite, not ground truth.
A5: FOUR AXES (each 0-1):
A6: axis_x_engagement 0 = no task ............... 1 = continuous control at capacity
A7: axis_y_action_timescale 0 = single ballistic act .. 1 = continuous, non-stationary
A8: axis_z_surprise_timescale 0 = no perturbation ...... 1 = non-stationary statistical drift
A9: axis_rho_predictiveness 0 = pure exogenous salience 1 = task-relevant performance error
A10: (rho is only meaningful when z > ~0.05; at z~0 it is a placeholder.)
A12: is_paradigm / paradigm_kind:
A13: empirical = actually runs a paradigm (pins a point): behaviour, EEG/MEG, fMRI, TMS, ephys.
A14: simulation = instantiates a paradigm in silico: computational model, robotics.
A15: theory/review = describes/theorises; occupies the region diffusely (plotted faded).
... A26: Full rule tables are in scoring_rubric.py (delivered alongside this file).

Sheet Axis Fla
A1: Paradigm Space axis and scale
A2: Axis | B2: Name | C2: Def | D2: Scale | E2: Intuition | F2: note
A3: x axis: | B3: motor task difficulty (te): | C3: The capacity the task commits, from passive stimulation with no task at all, through a comfortable discrete response, to continuous control at the stability boundary | D3: (0, 0'16, 0'33, 0'5, 0'66, 0'83, 1) = (no task, no output, discrete, discrete sust, cont. Control, cont. Control non stat) | K3: =1/6 -> 0.16666667 | L3: =1/7 -> 0.14285714 | O3: x axis: | P3: y axis: | Q3: z axis: | R3: r axis: | S3: year axis: | T3: t axis
A4: y axis: | B4: motor task task timescale (t_t) | C4: The window over which the motor command stays open to revision, from a single ballistic commitment to continuous non-stationary control | D4: (0, 0'14, 0'28, 0'43, 0'57, 0'71, 0'86, 1) = (no action, discrete, discrete + correction, seq of discrete, cont stat, cont non-stat, ext naturalistic) | K4: =K3*2 -> 0.33333333 | L4: =L3*2 -> 0.28571429
A5: z axis: | B5: external surprise hierarchy(s_t) | C5: The horizon over which the perturbing event's statistics unfold, and hence the hierarchical depth needed to estimate them: a single ash is punctate, a volatile schedule is deep | D5: (0, 0'16, 0'33, 0'5, 0'66, 0'83, 1) = (no surp, single pulse, short struct, sust/step, slow stat drift, non-stat changing env) | E5: how deep a model is needed to explain the event | K5: =K3*3 -> 0.5 | L5: =L3*3 -> 0.42857143
A6: year axis: | B6: year axis | C6: Publication year axis, used for time evolution of the paradigms | D6: year of publication | K6: =K3*5 -> 0.83333333 | L6: =L3*5 -> 0.71428571
A7: t axis | B7: Task relevance of the external stimuli | C7: Relevance of the external stimuli, going from 0 being completelly irrevelant (and therefore with the command to ignore it) and 1 completelly relevant for the task (for instance, when you hear a noise change task/target) | L7: =L3*6 -> 0.85714286
A8: s axis | B8: magnitude of external surprise | C8: The size of the sensory prediction error the event delivers at the moment it arrives, measured in units of the expected variability of the channel it arrives on. Both a very intense stimulus and a very improbable one produce a large error: intensity widens the departure from the prediction, rarity narrows the prediction. This is a property of a sample: how improbable this event was. | D8: (0, 0.17, 0.33, 0.5, 0.67, 0.83, 1) = (none, near-threshold or frequent, detectable and common, suprathreshold and moderately rare, strong and rare, very intense and rare, maximal). | E8: how large the error is before any explaining happens. | F8: This definition can be interpreted as the intuition behind defining it as "−log p of the event". However, this definition requires a model, are we assuming each paradigm has an assigned model?????? Double check with rory whether this scale makes sense with what we were discussing ieri.
A9: x_1 | B9: non-motor task difficulty | C9: The capacity the task commits to computations that do not issue a motor command: perceptual discrimination, evidence accumulation, maintenance in memory, application of a learned rule. Exactly the same reading as x, transposed to the perceptual and cognitive side of the hierarchy — from no demand at all, through a comfortable single-feature judgement, to two streams held concurrently at their joint capacity limit. | D9: (0, 0.17, 0.33, 0.5, 0.67, 0.83, 1) = (none, monitoring/detection, easy discrimination, near-threshold or rule-based judgement, decision under uncertainty, working-memory or dual-task load, at capacity)
A10: y_1 | B10: non-motor task timescale | C10: The window over which the estimate stays open to revision, as y is the window over which the command stays open. From a judgement that closes at the response, through beliefs that carry across trials, to a hidden variable tracked continuously with no closing point. | D10: (0, 0.14, 0.29, 0.43, 0.57, 0.71, 0.86, 1) = (none, single closed judgement, revisable within trial, within-trial accumulation, across-trial learning, across-block adaptation, session-long tracking, open-ended) | K10: (0, 0'16, 0'33, 0'5, 0'66, 0'83, 1) = (
A12: Surprise related axis are defined for each external surprise identified. Given Ns external surprise identifies we have 3 x Ns axis. | K12: (0, 0'14, 0'28, 0'43, 0'57, 0'71, 0'86, 1) = (
A16: r axis: | B16: Endogenous or exogenous surprise | C16: The correlation between the perturbation and the task-relevant variable, from pure exogenous salience at ρ= 0 to a performance error at ρ= 1. | K16: =K3*4 -> 0.66666667 | L16: =L3*4 -> 0.57142857
A19: Computational space
A20: Computational accounts (first cathegorical)
A21: SAL: | B21: Saliency detection

Sheet Axis Fla criteria
A1: Axis Fla - scoring criteria
A3: Every rung is a design feature readable from a Methods section. Scores are a reproducible starting point, not ground truth; overwrite freely. | B3: Since we are scoring the experimentla paradgims, we might define one entry (row) for each experimental paradigm, even if they are considered in the same paper (possible agreggations may be considered afterwards, or cluster analysis on the experimental paradigms)
A5: Decision rules
A6: R1 What counts as an external event | B6: An event scores on z/t/s/r only if it arrives while the task is already running - after the command has been issued or while an estimate is open - or if it is task-irrelevant. The imperative go-cue that starts a trial is part of the task, not a surprise. Without this rule every cued paradigm gets z > 0 and the axis stops discriminating.
A7: R2 One event per row | B7: Score the event the paper manipulates. Name it in the note. Papers with genuinely two manipulated events are flagged for a second column block.
A8: R3 Score the design, never the result | B8: Rungs are read from Methods. 'Subjects were slowed by the tone' is a result; 'a 100 dB tone occurred on 10% of trials' is a design.
A9: R4 Score what the subject was asked to do, not what the effector did | B9: A reflex evoked in a passive subject is y = 0 on the motor axis even though muscles moved; the ongoing postural command, if any, sets y.
A10: R5 Empty, not zero | B10: z = 0 leaves t, s and r empty. A missing event has no relevance and no magnitude, and zeros would create a spurious cluster at the origin.
A11: R6 Not every reference is a paradigm | B11: Lesion series, autopsy studies, microstimulation mapping, reviews and pure theory get scorable = no and a reason. Forcing them to the origin would invent a dense cluster there and corrupt any coverage or gap statistic.
A12: R7 Round to the rung | B12: Only the tabulated values are used. If a paper sits between two rungs, take the lower one and say so in the note.
A13: R8 Confidence is part of the score | B13: hi = the paradigm is known in detail; md = determined by title and summary; lo = inferred, must be checked before use. Any claim about coverage should be re-run with lo rows dropped.
A15: x motor task difficulty (t_e)
A16: value | B16: label | C16: operational test
A17: 0 | B17: no task | C17: No instruction to act. Passive stimulation, rest, anaesthesia, free rest.
A18: 0.17 | B18: task, no motor output | C18: There is a task but no measured effector output: perceptual report by verbal rating, delayed report, or observation only. Also: hold still.
A19: 0.33 | B19: discrete response | C19: One self-paced or cued discrete response per trial with generous tolerance: a button press, a reach to a large target, a saccade.
A20: 0.5 | B20: discrete, precision-constrained | C20: Same, but a speed, accuracy or force constraint binds: small target, deadline, penalty region, required trajectory.
A21: 0.67 | B21: sustained output | C21: Output must be held, not just emitted: isometric force hold, posture, fixation, sustained grip. Effort is continuous but the goal is static.
A22: 0.83 | B22: continuous control, stationary | C22: Closed loop with a moving goal and stationary plant: tracking, pursuit, steering, balancing on stable support, isometric forces.
A23: 1 | B23: continuous control, non-stationary | C23: As above but the plant or its cost is non-stationary, or control runs at the stability boundary: unstable loads, changing dynamics, near-fall.
A25: y motor task timescale (t_t)
A26: value | B26: label | C26: operational test
A27: 0 | B27: no action | C27: No motor command is issued at all.
A28: 0.14 | B28: discrete ballistic | C28: One command, closed at onset. Too short or too fast to be revised in flight; the trial ends with the response.
A29: 0.29 | B29: discrete + online correction | C29: One movement, long enough that feedback can revise it in flight: target jumps, mid-flight perturbations, corrections measurable.
A30: 0.43 | B30: sustained hold | C30: A single goal held open for seconds: isometric force, posture, fixation. Continuously revisable, but with no trajectory to revise.
A31: 0.57 | B31: sequence of discrete acts | C31: Several commands chained within a trial, revisable between elements: sequential reaching, speech, multi-step task.
A32: 0.71 | B32: continuous, stationary | C32: One command open for the whole trial with a moving goal and fixed statistics: tracking or pursuit of a stationary-statistics target.
